Workbook

Sheet Сроки и стоимость
P2: Издержки (аренда, налоги и т.д.): | X2: 0
AL3: площадь | AM3: =B38*'Атлант, Великан'!M127+IF(AM14=TRUE,(B46+D46+F46+H46+J46)*B38*(MAX(L46,2)-1),0)+IF(AM15=TRUE,B50*F50*(MAX(L50,2)-1),0)+IF(AM16=TRUE,B54*F54*(MAX(L54,2)-1),0)+IF(AM17=TRUE,B58*F58*(MAX(L58,2)-1),0) | AO3: спринт-м двускатный | AP3: спринт-м односкатный | AQ3: спринт-2м двускатный | AR3: спринт-2м односкатный | AS3: великан двускатный | AT3: великан односкатный | AU3: великан плоская | AV3: великан многоскатная | AW3: атлант двускатный | AX3: атлант односкатный | AY3: атлант плоская | AZ3: атлант многоскатная | BA3: атлант-м двускатный | BB3: атлант-м односкатный | BC3: атлант-м плоская | BD3: атлант-м многоскатная | BE3: крон двусткатный | BF3: крон односкатный | BI3: площадь | BJ3: =Y38*'Атлант, Великан'!AJ127+IF(BJ14=TRUE,(Y46+AA46+AC46+AE46+AG46)*Y38*(MAX(AI46,2)-1),0)+IF(BJ15=TRUE,Y50*AC50*(MAX(AI50,2)-1),0)+IF(BJ16=TRUE,Y54*AC54*(MAX(AI54,2)-1),0)+IF(BJ17=TRUE,Y58*AC58*(MAX(AI58,2)-1),0) | BL3: спринт-м двускатный | BM3: спринт-м односкатный | BN3: спринт-2м двускатный | BO3: спринт-2м односкатный | BP3: великан двускатный | BQ3: великан односкатный | BR3: великан плоская | BS3: великан многоскатная | BT3: атлант двускатный | BU3: атлант односкатный | BV3: атлант плоская | BW3: атлант многоскатная | BX3: атлант-м двускатный | BY3: атлант-м односкатный | BZ3: атлант-м плоская | CA3: атлант-м многоскатная | CB3: крон двусткатный | CC3: крон односкатный
AL4: база | AM4: 80000 | AO4: =Спринт!B2 | AP4: =Спринт!B38 | AQ4: =Спринт!B14 | AR4: =Спринт!B50 | AS4: =IF($D$33<=1,'Атлант, Великан'!$B$1,'Атлант, Великан'!$B$31+($D$33-1)*'Атлант, Великан'!$C$31) | AT4: =IF($D$33<=1,'Атлант, Великан'!$B$16, 'Атлант, Великан'!$B$56+($D$33-1)*'Атлант, Великан'!$C$56) | AU4: ='Атлант, Великан'!$B$80+($D$33-1)*'Атлант, Великан'!$C$80 | AV4: ='Атлант, Великан'!$B$104+($D$33-1)*'Атлант, Великан'!$C$104 | AW4: =IF($D$33<=1,'Атлант, Великан'!$B$3,'Атлант, Великан'!$B$33+($D$33-1)*'Атлант, Великан'!$C$33) | AX4: =IF($D$33<=1,'Атлант, Великан'!$B$18,'Атлант, Великан'!$B$58+($D$33-1)*'Атлант, Великан'!$C$58) | AY4: ='Атлант, Великан'!$B$82+($D$33-1)*'Атлант, Великан'!$C$82 | AZ4: ='Атлант, Великан'!$B$106+($D$33-1)*'Атлант, Великан'!$C$106 | BA4: =IF($D$33<=1,'Атлант, Великан'!$B$5,'Атлант, Великан'!$B$35+($D$33-1)*'Атлант, Великан'!$C$35) | BB4: =IF($D$33<=1,'Атлант, Великан'!$B$20,'Атлант, Великан'!$B$60+($D$33-1)*'Атлант, Великан'!$C$60) | BC4: ='Атлант, Великан'!$B$84+($D$33-1)*'Атлант, Великан'!$C$84 | BD4: ='Атлант, Великан'!$B$108+($D$33-1)*'Атлант, Великан'!$C$108 | BE4: =Спринт!B26 | BF4: =Спринт!B62 | BI4: база | BJ4: 80000 | BL4: ='Атлант, Великан'!B304 | BM4: ='Атлант, Великан'!B304 | BN4: ='Атлант, Великан'!B304 | BO4: ='Атлант, Великан'!B304 | BP4: ='Атлант, Великан'!B302 | BQ4: ='Атлант, Великан'!B302 | BR4: ='Атлант, Великан'!B302 | BS4: ='Атлант, Великан'!B302 | BT4: ='Атлант, Великан'!B302 | BU4: ='Атлант, Великан'!B302 | BV4: ='Атлант, Великан'!B302 | BW4: ='Атлант, Великан'!B302 | BX4: ='Атлант, Великан'!B302 | BY4: ='Атлант, Великан'!B302 | BZ4: ='Атлант, Великан'!B302 | CA4: ='Атлант, Великан'!B302 | CB4: ='Атлант, Великан'!B304 | CC4: ='Атлант, Великан'!B304
AL5: страна | AM5: 1 | AO5: =CHOOSE($AM$5,1,'Атлант, Великан'!$B$162) | AP5: =CHOOSE($AM$5,1,'Атлант, Великан'!$B$162) | AQ5: =CHOOSE($AM$5,1,'Атлант, Великан'!$B$162) | AR5: =CHOOSE($AM$5,1,'Атлант, Великан'!$B$162) | AS5: =CHOOSE($AM$5,1,'Атлант, Великан'!$B$162) | AT5: =CHOOSE($AM$5,1,'Атлант, Великан'!$B$162) | AU5: =CHOOSE($AM$5,1,'Атлант, Великан'!$B$162) | AV5: =CHOOSE($AM$5,1,'Атлант, Великан'!$B$162) | ... BF5: =CHOOSE($AM$5,1,'Атлант, Великан'!$B$162) | BI5: страна | BJ5: =AM5 | BL5: 1 | BM5: 1 | BN5: 1 | BO5: 1 | BP5: 1 | BQ5: 1 | BR5: 1 | BS5: 1 | BT5: 1 | BU5: 1 | BV5: 1 | BW5: 1 | BX5: 1 | BY5: 1 | BZ5: 1 | CA5: 1 | CB5: 1 | CC5: 1
AL6: сейсмика | AM6: 1 | AO6: =CHOOSE($AM$6,'Атлант, Великан'!$B$164,'Атлант, Великан'!$B$165,'Атлант, Великан'!$B$166,'Атлант, Великан'!$B$167) | AP6: =CHOOSE($AM$6,'Атлант, Великан'!$B$164,'Атлант, Великан'!$B$165,'Атлант, Великан'!$B$166,'Атлант, Великан'!$B$167) | AQ6: =CHOOSE($AM$6,'Атлант, Великан'!$B$164,'Атлант, Великан'!$B$165,'Атлант, Великан'!$B$166,'Атлант, Великан'!$B$167) | AR6: =CHOOSE($AM$6,'Атлант, Великан'!$B$164,'Атлант, Великан'!$B$165,'Атлант, Великан'!$B$166,'Атлант, Великан'!$B$167) | AS6: =CHOOSE($AM$6,'Атлант, Великан'!$B$164,'Атлант, Великан'!$B$165,'Атлант, Великан'!$B$166,'Атлант, Великан'!$B$167) | AT6: =CHOOSE($AM$6,'Атлант, Великан'!$B$164,'Атлант, Великан'!$B$165,'Атлант, Великан'!$B$166,'Атлант, Великан'!$B$167) | AU6: =CHOOSE($AM$6,'Атлант, Великан'!$B$164,'Атлант, Великан'!$B$165,'Атлант, Великан'!$B$166,'Атлант, Великан'!$B$167) | AV6: =CHOOSE($AM$6,'Атлант, Великан'!$B$164,'Атлант, Великан'!$B$165,'Атлант, Великан'!$B$166,'Атлант, Великан'!$B$167) | ... BF6: =CHOOSE($AM$6,'Атлант, Великан'!$B$164,'Атлант, Великан'!$B$165,'Атлант, Великан'!$B$166,'Атлант, Великан'!$B$167) | BI6: сейсмика | BJ6: =AM6 | BL6: 0 | BM6: 0 | BN6: 0 | BO6: 0 | BP6: 0 | BQ6: 0 | BR6: 0 | BS6: 0 | BT6: 0 | BU6: 0 | BV6: 0 | BW6: 0 | BX6: 0 | BY6: 0 | BZ6: 0 | CA6: 0 | CB6: 0 | CC6: 0
AL7: тип здания | AM7: 3 | AO7: =CHOOSE($AM$7,1,0,0,0,0,0) | AP7: =CHOOSE($AM$7,1,0,0,0,0,0) | AQ7: =CHOOSE($AM$7,0,1,0,0,0,0) | AR7: =CHOOSE($AM$7,0,1,0,0,0,0) | AS7: =CHOOSE($AM$7,0,0,1,0,0,0) | AT7: =CHOOSE($AM$7,0,0,1,0,0,0) | AU7: =CHOOSE($AM$7,0,0,1,0,0,0) | AV7: =CHOOSE($AM$7,0,0,1,0,0,0) | AW7: =CHOOSE($AM$7,0,0,0,1,0,0) | AX7: =CHOOSE($AM$7,0,0,0,1,0,0) | AY7: =CHOOSE($AM$7,0,0,0,1,0,0) | AZ7: =CHOOSE($AM$7,0,0,0,1,0,0) | BA7: =CHOOSE($AM$7,0,0,0,0,1,0) | BB7: =CHOOSE($AM$7,0,0,0,0,1,0) | BC7: =CHOOSE($AM$7,0,0,0,0,1,0) | BD7: =CHOOSE($AM$7,0,0,0,0,1,0) | BE7: =CHOOSE($AM$7,0,0,0,0,0,1) | BF7: =CHOOSE($AM$7,0,0,0,0,0,1) | BI7: тип здания | BJ7: =AM7 | BL7: =CHOOSE($AM$7,1,0,0,0,0,0) | BM7: =CHOOSE($AM$7,1,0,0,0,0,0) | BN7: =CHOOSE($AM$7,0,1,0,0,0,0) | BO7: =CHOOSE($AM$7,0,1,0,0,0,0) | BP7: =CHOOSE($AM$7,0,0,1,0,0,0) | BQ7: =CHOOSE($AM$7,0,0,1,0,0,0) | BR7: =CHOOSE($AM$7,0,0,1,0,0,0) | BS7: =CHOOSE($AM$7,0,0,1,0,0,0) | BT7: =CHOOSE($AM$7,0,0,0,1,0,0) | BU7: =CHOOSE($AM$7,0,0,0,1,0,0) | BV7: =CHOOSE($AM$7,0,0,0,1,0,0) | BW7: =CHOOSE($AM$7,0,0,0,1,0,0) | BX7: =CHOOSE($AM$7,0,0,0,0,1,0) | BY7: =CHOOSE($AM$7,0,0,0,0,1,0) | BZ7: =CHOOSE($AM$7,0,0,0,0,1,0) | CA7: =CHOOSE($AM$7,0,0,0,0,1,0) | CB7: =CHOOSE($AM$7,0,0,0,0,0,1) | CC7: =CHOOSE($AM$7,0,0,0,0,0,1)
AK8: проектирование | AL8: КМ | AM8: TRUE | BH8: проектирование | BI8: КМ | BJ8: =AM8
Y9: стоимость проектных работ КМ | Z9: =(MAX(AO79:BF79)+MAX(BL79:CC79))/1000*(100%+X2) | AB9: тыс. руб | AL9: АС | AM9: FALSE | BI9: АС | BJ9: =AM9
S10: срок проектирования КМ | Z10: =MAX(AO80:BF80)+MAX(BL80:CC80) | AB10: раб. дней | AL10: подстропильная ферма | AM10: FALSE | AO10: ='Атлант, Великан'!$F$296 | AP10: ='Атлант, Великан'!$F$296 | AQ10: ='Атлант, Великан'!$F$296 | AR10: ='Атлант, Великан'!$F$296 | AS10: ='Атлант, Великан'!$F$296 | AT10: ='Атлант, Великан'!$F$296 | AU10: ='Атлант, Великан'!$F$296 | AV10: ='Атлант, Великан'!$F$296 | ... BF10: ='Атлант, Великан'!$F$296 | BI10: подстропильная ферма | BJ10: =AM10 | BL10: 0 | BM10: 0 | BN10: 0 | BO10: 0 | BP10: 0 | BQ10: 0 | BR10: 0 | BS10: 0 | BT10: 0 | BU10: 0 | BV10: 0 | BW10: 0 | BX10: 0 | BY10: 0 | BZ10: 0 | CA10: 0 | CB10: 0 | CC10: 0
AK11: параметры здания | AL11: кровля | AM11: 2 | AO11: =CHOOSE($AM$11,0,1,0,0) | AP11: =CHOOSE($AM$11,1,0,0,0) | AQ11: =CHOOSE($AM$11,0,1,0,0) | AR11: =CHOOSE($AM$11,1,0,0,0) | AS11: =CHOOSE($AM$11,0,1,0,0) | AT11: =CHOOSE($AM$11,1,0,0,0) | AU11: =CHOOSE($AM$11,0,0,1,0) | AV11: =CHOOSE($AM$11,0,0,0,1) | AW11: =CHOOSE($AM$11,0,1,0,0) | AX11: =CHOOSE($AM$11,1,0,0,0) | AY11: =CHOOSE($AM$11,0,0,1,0) | AZ11: =CHOOSE($AM$11,0,0,0,1) | BA11: =CHOOSE($AM$11,0,1,0,0) | BB11: =CHOOSE($AM$11,1,0,0,0) | BC11: =CHOOSE($AM$11,0,0,1,0) | BD11: =CHOOSE($AM$11,0,0,0,1) | BE11: =CHOOSE($AM$11,0,1,0,0) | BF11: =CHOOSE($AM$11,1,0,0,0) | BH11: параметры здания | BI11: кровля | BJ11: =AM11 | BL11: =CHOOSE($AM$11,0,1,0,0) | BM11: =CHOOSE($AM$11,1,0,0,0) | BN11: =CHOOSE($AM$11,0,1,0,0) | BO11: =CHOOSE($AM$11,1,0,0,0) | BP11: =CHOOSE($AM$11,0,1,0,0) | BQ11: =CHOOSE($AM$11,1,0,0,0) | BR11: =CHOOSE($AM$11,0,0,1,0) | BS11: =CHOOSE($AM$11,0,0,0,1) | BT11: =CHOOSE($AM$11,0,1,0,0) | BU11: =CHOOSE($AM$11,1,0,0,0) | BV11: =CHOOSE($AM$11,0,0,1,0) | BW11: =CHOOSE($AM$11,0,0,0,1) | BX11: =CHOOSE($AM$11,0,1,0,0) | BY11: =CHOOSE($AM$11,1,0,0,0) | BZ11: =CHOOSE($AM$11,0,0,1,0) | CA11: =CHOOSE($AM$11,0,0,0,1) | CB11: =CHOOSE($AM$11,0,1,0,0) | CC11: =CHOOSE($AM$11,1,0,0,0)
S12: Конструктив | V12: Средняя металлоемкость, кг/м2 | Z12: Стоимость проектных работ, тыс.руб/т | AL12: пролеты | AM12: 1 | AO12: 0 | AP12: 0 | AQ12: 0 | AR12: 0 | AS12: ='Атлант, Великан'!V135 | AT12: ='Атлант, Великан'!V135 | AU12: ='Атлант, Великан'!V135 | AV12: ='Атлант, Великан'!V135 | AW12: ='Атлант, Великан'!V144 | AX12: ='Атлант, Великан'!V144 | AY12: ='Атлант, Великан'!V144 | AZ12: ='Атлант, Великан'!V144 | BA12: ='Атлант, Великан'!V153 | BB12: ='Атлант, Великан'!V153 | BC12: ='Атлант, Великан'!V153 | BD12: ='Атлант, Великан'!V153 | BE12: 0 | BF12: 0 | BI12: пролеты | BJ12: =AM12
AL13: шаг рам | AM13: 1 | AO13: =CHOOSE($AM$13,0,Спринт!$B$77) | AP13: =CHOOSE($AM$13,0,Спринт!$B$77) | AQ13: =CHOOSE($AM$13,0,Спринт!$B$77) | AR13: =CHOOSE($AM$13,0,Спринт!$B$77) | AS13: =CHOOSE($AM$13,0,'Атлант, Великан'!$B$160) | AT13: =CHOOSE($AM$13,0,'Атлант, Великан'!$B$160) | AU13: =CHOOSE($AM$13,0,'Атлант, Великан'!$B$160) | AV13: =CHOOSE($AM$13,0,'Атлант, Великан'!$B$160) | AW13: =CHOOSE($AM$13,0,'Атлант, Великан'!$B$160) | AX13: =CHOOSE($AM$13,0,'Атлант, Великан'!$B$160) | AY13: =CHOOSE($AM$13,0,'Атлант, Великан'!$B$160) | AZ13: =CHOOSE($AM$13,0,'Атлант, Великан'!$B$160) | ... BD13: =CHOOSE($AM$13,0,'Атлант, Великан'!$B$160) | BE13: =CHOOSE($AM$13,0,Спринт!$B$77) | BF13: =CHOOSE($AM$13,0,Спринт!$B$77) | BI13: шаг рам | BJ13: =AM13
AL14: наличие в здании перекрытия | AM14: FALSE | AO14: ='Атлант, Великан'!$O$243 | AP14: ='Атлант, Великан'!$O$243 | AQ14: ='Атлант, Великан'!$O$243 | AR14: ='Атлант, Великан'!$O$243 | AS14: ='Атлант, Великан'!$O$243 | AT14: ='Атлант, Великан'!$O$243 | AU14: ='Атлант, Великан'!$O$243 | AV14: ='Атлант, Великан'!$O$243 | ... BF14: ='Атлант, Великан'!$O$243 | BI14: наличие в здании перекрытия | BJ14: =AM14 | BL14: ='Атлант, Великан'!$L$520 | BM14: ='Атлант, Великан'!$L$520 | BN14: ='Атлант, Великан'!$L$520 | BO14: ='Атлант, Великан'!$L$520 | BP14: ='Атлант, Великан'!$L$520 | BQ14: ='Атлант, Великан'!$L$520 | BR14: ='Атлант, Великан'!$L$520 | BS14: ='Атлант, Великан'!$L$520 | ... CC14: ='Атлант, Великан'!$L$520
S15: Спринт-М | V15: 25 | Z15: =CHOOSE($AM$11,AP78,AO78,0,0)/($AM$3*V15) | AL15: наличие в здании антресоли 1 | AM15: FALSE | AO15: ='Атлант, Великан'!$B$252*'Атлант, Великан'!$I$252 | AP15: ='Атлант, Великан'!$B$252*'Атлант, Великан'!$I$252 | AQ15: ='Атлант, Великан'!$B$252*'Атлант, Великан'!$I$252 | AR15: ='Атлант, Великан'!$B$252*'Атлант, Великан'!$I$252 | AS15: ='Атлант, Великан'!$B$252*'Атлант, Великан'!$I$252 | AT15: ='Атлант, Великан'!$B$252*'Атлант, Великан'!$I$252 | AU15: ='Атлант, Великан'!$B$252*'Атлант, Великан'!$I$252 | AV15: ='Атлант, Великан'!$B$252*'Атлант, Великан'!$I$252 | ... BF15: ='Атлант, Великан'!$B$252*'Атлант, Великан'!$I$252 | BI15: наличие в здании антресоли 1 | BJ15: =AM15 | BL15: ='Атлант, Великан'!$R$520 | BM15: ='Атлант, Великан'!$R$520 | BN15: ='Атлант, Великан'!$R$520 | BO15: ='Атлант, Великан'!$R$520 | BP15: ='Атлант, Великан'!$R$520 | BQ15: ='Атлант, Великан'!$R$520 | BR15: ='Атлант, Великан'!$R$520 | BS15: ='Атлант, Великан'!$R$520 | ... CC15: ='Атлант, Великан'!$R$520
S16: Спринт-2М | V16: 30 | Z16: =CHOOSE($AM$11,AR78,AQ78,0,0)/($AM$3*V16) | AL16: наличие в здании антресоли 2 | AM16: FALSE | AO16: ='Атлант, Великан'!$B$252*'Атлант, Великан'!$J$252 | AP16: ='Атлант, Великан'!$B$252*'Атлант, Великан'!$J$252 | AQ16: ='Атлант, Великан'!$B$252*'Атлант, Великан'!$J$252 | AR16: ='Атлант, Великан'!$B$252*'Атлант, Великан'!$J$252 | AS16: ='Атлант, Великан'!$B$252*'Атлант, Великан'!$J$252 | AT16: ='Атлант, Великан'!$B$252*'Атлант, Великан'!$J$252 | AU16: ='Атлант, Великан'!$B$252*'Атлант, Великан'!$J$252 | AV16: ='Атлант, Великан'!$B$252*'Атлант, Великан'!$J$252 | ... BF16: ='Атлант, Великан'!$B$252*'Атлант, Великан'!$J$252 | BI16: наличие в здании антресоли 2 | BJ16: =AM16
S17: Великан | V17: 35 | Z17: =CHOOSE($AM$11,AT78,AS78,AU78,AV78)/($AM$3*V17) | AL17: наличие в здании антресоли 3 | AM17: FALSE | AO17: ='Атлант, Великан'!$B$252*'Атлант, Великан'!$K$252 | AP17: ='Атлант, Великан'!$B$252*'Атлант, Великан'!$K$252 | AQ17: ='Атлант, Великан'!$B$252*'Атлант, Великан'!$K$252 | AR17: ='Атлант, Великан'!$B$252*'Атлант, Великан'!$K$252 | AS17: ='Атлант, Великан'!$B$252*'Атлант, Великан'!$K$252 | AT17: ='Атлант, Великан'!$B$252*'Атлант, Великан'!$K$252 | AU17: ='Атлант, Великан'!$B$252*'Атлант, Великан'!$K$252 | AV17: ='Атлант, Великан'!$B$252*'Атлант, Великан'!$K$252 | ... BF17: ='Атлант, Великан'!$B$252*'Атлант, Великан'!$K$252 | BI17: наличие в здании антресоли 3 | BJ17: =AM17
S18: Атлант | V18: 40 | Z18: =CHOOSE($AM$11,AX78,AW78,AY78,AZ78)/($AM$3*V18) | AL18: наличие в здании опорного крана | AM18: FALSE | AO18: 0 | AP18: 0 | AQ18: 0 | AR18: 0 | AS18: =IF($AM$18=TRUE,IF($D$33<=1,'Атлант, Великан'!$B$13,'Атлант, Великан'!$B$49+IF('Сроки и стоимость'!$AM$19=1,0,1)*'Атлант, Великан'!$B$51*('Сроки и стоимость'!$F$61-1)+('Сроки и стоимость'!$F$61-1)*'Атлант, Великан'!$B$50),0) | AT18: =IF($AM$18=TRUE,IF($D$33<=1,'Атлант, Великан'!$B$28,'Атлант, Великан'!$B$73+IF('Сроки и стоимость'!$AM$19=1,0,1)*'Атлант, Великан'!$B$75*('Сроки и стоимость'!$F$61-1)+('Сроки и стоимость'!$F$61-1)*'Атлант, Великан'!$B$74),0) | AU18: =IF($AM$18=TRUE,IF($D$33<=1,'Атлант, Великан'!$B$97,'Атлант, Великан'!$B$97+IF('Сроки и стоимость'!$AM$19=1,0,1)*'Атлант, Великан'!$B$99*('Сроки и стоимость'!$F$61-1)+('Сроки и стоимость'!$F$61-1)*'Атлант, Великан'!$B$98),0) | AV18: =IF($AM$18=TRUE,IF($D$33<=1,'Атлант, Великан'!$B$121,'Атлант, Великан'!$B$121+IF('Сроки и стоимость'!$AM$19=1,0,1)*'Атлант, Великан'!$B$123*('Сроки и стоимость'!$F$61-1)+('Сроки и стоимость'!$F$61-1)*'Атлант, Великан'!$B$122),0) | AW18: =IF($AM$18=TRUE,IF($D$33<=1,'Атлант, Великан'!$B$13,'Атлант, Великан'!$B$49+IF('Сроки и стоимость'!$AM$19=1,0,1)*'Атлант, Великан'!$B$51*('Сроки и стоимость'!$F$61-1)+('Сроки и стоимость'!$F$61-1)*'Атлант, Великан'!$B$50),0) | AX18: =IF($AM$18=TRUE,IF($D$33<=1,'Атлант, Великан'!$B$28,'Атлант, Великан'!$B$73+IF('Сроки и стоимость'!$AM$19=1,0,1)*'Атлант, Великан'!$B$75*('Сроки и стоимость'!$F$61-1)+('Сроки и стоимость'!$F$61-1)*'Атлант, Великан'!$B$74),0) | AY18: =IF($AM$18=TRUE,IF($D$33<=1,'Атлант, Великан'!$B$97,'Атлант, Великан'!$B$97+IF('Сроки и стоимость'!$AM$19=1,0,1)*'Атлант, Великан'!$B$99*('Сроки и стоимость'!$F$61-1)+('Сроки и стоимость'!$F$61-1)*'Атлант, Великан'!$B$98),0) | AZ18: =IF($AM$18=TRUE,IF($D$33<=1,'Атлант, Великан'!$B$121,'Атлант, Великан'!$B$121+IF('Сроки и стоимость'!$AM$19=1,0,1)*'Атлант, Великан'!$B$123*('Сроки и стоимость'!$F$61-1)+('Сроки и стоимость'!$F$61-1)*'Атлант, Великан'!$B$122),0) | BA18: =IF($AM$18=TRUE,IF($D$33<=1,'Атлант, Великан'!$B$13,'Атлант, Великан'!$B$49+IF('Сроки и стоимость'!$AM$19=1,0,1)*'Атлант, Великан'!$B$51*('Сроки и стоимость'!$F$61-1)+('Сроки и стоимость'!$F$61-1)*'Атлант, Великан'!$B$50),0) | BB18: =IF($AM$18=TRUE,IF($D$33<=1,'Атлант, Великан'!$B$28,'Атлант, Великан'!$B$73+IF('Сроки и стоимость'!$AM$19=1,0,1)*'Атлант, Великан'!$B$75*('Сроки и стоимость'!$F$61-1)+('Сроки и стоимость'!$F$61-1)*'Атлант, Великан'!$B$74),0) | BC18: =IF($AM$18=TRUE,IF($D$33<=1,'Атлант, Великан'!$B$97,'Атлант, Великан'!$B$97+IF('Сроки и стоимость'!$AM$19=1,0,1)*'Атлант, Великан'!$B$99*('Сроки и стоимость'!$F$61-1)+('Сроки и стоимость'!$F$61-1)*'Атлант, Великан'!$B$98),0) | BD18: =IF($AM$18=TRUE,IF($D$33<=1,'Атлант, Великан'!$B$121,'Атлант, Великан'!$B$121+IF('Сроки и стоимость'!$AM$19=1,0,1)*'Атлант, Великан'!$B$123*('Сроки и стоимость'!$F$61-1)+('Сроки и стоимость'!$F$61-1)*'Атлант, Великан'!$B$122),0) | BE18: 0 | BF18: 0 | BI18: наличие в здании опорного крана | BJ18: =AM18
S19: Атлант-М | V19: 36 | Z19: =CHOOSE($AM$11,BB78,BA78,BC78,BD78)/($AM$3*V19) | AL19: грузоподъемность опорного крана | AM19: 1 | BI19: грузоподъемность опорного крана | BJ19: =AM19
S20: Крон | V20: 30 | Z20: =CHOOSE($AM$11,BF78,BE78,0,0)/($AM$3*V20) | AL20: наличие в здании подвесного крана | AM20: FALSE | AO20: 0 | AP20: 0 | AQ20: 0 | AR20: 0 | AS20: =IF($AM$20=TRUE,IF($D$33<=1,'Атлант, Великан'!$B$14,'Атлант, Великан'!$B$52+IF('Сроки и стоимость'!$AM$21=1,0,1)*'Атлант, Великан'!$B$54*('Сроки и стоимость'!$F$66-1)+('Сроки и стоимость'!$F$66-1)*'Атлант, Великан'!$B$53),0) | AT20: =IF($AM$20=TRUE,IF($D$33<=1,'Атлант, Великан'!$B$29,'Атлант, Великан'!$B$76+IF('Сроки и стоимость'!$AM$21=1,0,1)*'Атлант, Великан'!$B$78*('Сроки и стоимость'!$F$66-1)+('Сроки и стоимость'!$F$66-1)*'Атлант, Великан'!$B$77),0) | AU20: =IF($AM$20=TRUE,IF($D$33<=1,'Атлант, Великан'!$B$100,'Атлант, Великан'!$B$100+IF('Сроки и стоимость'!$AM$21=1,0,1)*'Атлант, Великан'!$B$102*('Сроки и стоимость'!$F$66-1)+('Сроки и стоимость'!$F$66-1)*'Атлант, Великан'!$B$101),0) | AV20: =IF($AM$20=TRUE,IF($D$33<=1,'Атлант, Великан'!$B$124,'Атлант, Великан'!$B$124+IF('Сроки и стоимость'!$AM$21=1,0,1)*'Атлант, Великан'!$B$126*('Сроки и стоимость'!$F$66-1)+('Сроки и стоимость'!$F$66-1)*'Атлант, Великан'!$B$125),0) | AW20: =IF($AM$20=TRUE,IF($D$33<=1,'Атлант, Великан'!$B$14,'Атлант, Великан'!$B$52+IF('Сроки и стоимость'!$AM$21=1,0,1)*'Атлант, Великан'!$B$54*('Сроки и стоимость'!$F$66-1)+('Сроки и стоимость'!$F$66-1)*'Атлант, Великан'!$B$53),0) | AX20: =IF($AM$20=TRUE,IF($D$33<=1,'Атлант, Великан'!$B$29,'Атлант, Великан'!$B$76+IF('Сроки и стоимость'!$AM$21=1,0,1)*'Атлант, Великан'!$B$78*('Сроки и стоимость'!$F$66-1)+('Сроки и стоимость'!$F$66-1)*'Атлант, Великан'!$B$77),0) | AY20: =IF($AM$20=TRUE,IF($D$33<=1,'Атлант, Великан'!$B$100,'Атлант, Великан'!$B$100+IF('Сроки и стоимость'!$AM$21=1,0,1)*'Атлант, Великан'!$B$102*('Сроки и стоимость'!$F$66-1)+('Сроки и стоимость'!$F$66-1)*'Атлант, Великан'!$B$101),0) | AZ20: =IF($AM$20=TRUE,IF($D$33<=1,'Атлант, Великан'!$B$124,'Атлант, Великан'!$B$124+IF('Сроки и стоимость'!$AM$21=1,0,1)*'Атлант, Великан'!$B$126*('Сроки и стоимость'!$F$66-1)+('Сроки и стоимость'!$F$66-1)*'Атлант, Великан'!$B$125),0) | BA20: =IF($AM$20=TRUE,IF($D$33<=1,'Атлант, Великан'!$B$14,'Атлант, Великан'!$B$52+IF('Сроки и стоимость'!$AM$21=1,0,1)*'Атлант, Великан'!$B$54*('Сроки и стоимость'!$F$66-1)+('Сроки и стоимость'!$F$66-1)*'Атлант, Великан'!$B$53),0) | BB20: =IF($AM$20=TRUE,IF($D$33<=1,'Атлант, Великан'!$B$29,'Атлант, Великан'!$B$76+IF('Сроки и стоимость'!$AM$21=1,0,1)*'Атлант, Великан'!$B$78*('Сроки и стоимость'!$F$66-1)+('Сроки и стоимость'!$F$66-1)*'Атлант, Великан'!$B$77),0) | BC20: =IF($AM$20=TRUE,IF($D$33<=1,'Атлант, Великан'!$B$100,'Атлант, Великан'!$B$100+IF('Сроки и стоимость'!$AM$21=1,0,1)*'Атлант, Великан'!$B$102*('Сроки и стоимость'!$F$66-1)+('Сроки и стоимость'!$F$66-1)*'Атлант, Великан'!$B$101),0) | BD20: =IF($AM$20=TRUE,IF($D$33<=1,'Атлант, Великан'!$B$124,'Атлант, Великан'!$B$124+IF('Сроки и стоимость'!$AM$21=1,0,1)*'Атлант, Великан'!$B$126*('Сроки и стоимость'!$F$66-1)+('Сроки и стоимость'!$F$66-1)*'Атлант, Великан'!$B$125),0) | BE20: 0 | BF20: 0 | BI20: наличие в здании подвесного крана | BJ20: =AM20
AL21: грузоподъемность подвесного крана | AM21: 1 | BI21: грузоподъемность подвесного крана | BJ21: =AM21
AL22: лестница | AM22: FALSE | BI22: лестница | BJ22: =AM22
AK23: под Ж/Б ступени | AL23: одномаршевая | AM23: FALSE | AO23: =IF($AM$23=TRUE,'Атлант, Великан'!$B$231*'Сроки и стоимость'!$F$71,0) | AP23: =IF($AM$23=TRUE,'Атлант, Великан'!$B$231*'Сроки и стоимость'!$F$71,0) | AQ23: =IF($AM$23=TRUE,'Атлант, Великан'!$B$231*'Сроки и стоимость'!$F$71,0) | AR23: =IF($AM$23=TRUE,'Атлант, Великан'!$B$231*'Сроки и стоимость'!$F$71,0) | AS23: =IF($AM$23=TRUE,'Атлант, Великан'!$B$231*'Сроки и стоимость'!$F$71,0) | AT23: =IF($AM$23=TRUE,'Атлант, Великан'!$B$231*'Сроки и стоимость'!$F$71,0) | AU23: =IF($AM$23=TRUE,'Атлант, Великан'!$B$231*'Сроки и стоимость'!$F$71,0) | AV23: =IF($AM$23=TRUE,'Атлант, Великан'!$B$231*'Сроки и стоимость'!$F$71,0) | ... BF23: =IF($AM$23=TRUE,'Атлант, Великан'!$B$231*'Сроки и стоимость'!$F$71,0) | BH23: под Ж/Б ступени | BI23: одномаршевая | BJ23: =AM23
AL24: двухмаршевая | AM24: FALSE | AO24: =IF($AM$24=TRUE,'Атлант, Великан'!$B$232*'Сроки и стоимость'!$F$73,0) | AP24: =IF($AM$24=TRUE,'Атлант, Великан'!$B$232*'Сроки и стоимость'!$F$73,0) | AQ24: =IF($AM$24=TRUE,'Атлант, Великан'!$B$232*'Сроки и стоимость'!$F$73,0) | AR24: =IF($AM$24=TRUE,'Атлант, Великан'!$B$232*'Сроки и стоимость'!$F$73,0) | AS24: =IF($AM$24=TRUE,'Атлант, Великан'!$B$232*'Сроки и стоимость'!$F$73,0) | AT24: =IF($AM$24=TRUE,'Атлант, Великан'!$B$232*'Сроки и стоимость'!$F$73,0) | AU24: =IF($AM$24=TRUE,'Атлант, Великан'!$B$232*'Сроки и стоимость'!$F$73,0) | AV24: =IF($AM$24=TRUE,'Атлант, Великан'!$B$232*'Сроки и стоимость'!$F$73,0) | ... BF24: =IF($AM$24=TRUE,'Атлант, Великан'!$B$232*'Сроки и стоимость'!$F$73,0) | BI24: двухмаршевая | BJ24: =AM24
AL25: трехмаршевая | AM25: FALSE | AO25: =IF($AM$25=TRUE,'Атлант, Великан'!$B$233*'Сроки и стоимость'!$F$75,0) | AP25: =IF($AM$25=TRUE,'Атлант, Великан'!$B$233*'Сроки и стоимость'!$F$75,0) | AQ25: =IF($AM$25=TRUE,'Атлант, Великан'!$B$233*'Сроки и стоимость'!$F$75,0) | AR25: =IF($AM$25=TRUE,'Атлант, Великан'!$B$233*'Сроки и стоимость'!$F$75,0) | AS25: =IF($AM$25=TRUE,'Атлант, Великан'!$B$233*'Сроки и стоимость'!$F$75,0) | AT25: =IF($AM$25=TRUE,'Атлант, Великан'!$B$233*'Сроки и стоимость'!$F$75,0) | AU25: =IF($AM$25=TRUE,'Атлант, Великан'!$B$233*'Сроки и стоимость'!$F$75,0) | AV25: =IF($AM$25=TRUE,'Атлант, Великан'!$B$233*'Сроки и стоимость'!$F$75,0) | ... BF25: =IF($AM$25=TRUE,'Атлант, Великан'!$B$233*'Сроки и стоимость'!$F$75,0) | BI25: трехмаршевая | BJ25: =AM25
AL26: четырехмаршевая | AM26: FALSE | AO26: =IF($AM$26=TRUE,'Атлант, Великан'!$B$234*'Сроки и стоимость'!$F$77,0) | AP26: =IF($AM$26=TRUE,'Атлант, Великан'!$B$234*'Сроки и стоимость'!$F$77,0) | AQ26: =IF($AM$26=TRUE,'Атлант, Великан'!$B$234*'Сроки и стоимость'!$F$77,0) | AR26: =IF($AM$26=TRUE,'Атлант, Великан'!$B$234*'Сроки и стоимость'!$F$77,0) | AS26: =IF($AM$26=TRUE,'Атлант, Великан'!$B$234*'Сроки и стоимость'!$F$77,0) | AT26: =IF($AM$26=TRUE,'Атлант, Великан'!$B$234*'Сроки и стоимость'!$F$77,0) | AU26: =IF($AM$26=TRUE,'Атлант, Великан'!$B$234*'Сроки и стоимость'!$F$77,0) | AV26: =IF($AM$26=TRUE,'Атлант, Великан'!$B$234*'Сроки и стоимость'!$F$77,0) | ... BF26: =IF($AM$26=TRUE,'Атлант, Великан'!$B$234*'Сроки и стоимость'!$F$77,0) | BI26: четырехмаршевая | BJ26: =AM26
AK27: с металлическими ступенями | AL27: одномаршевая | AM27: FALSE | AO27: =IF($AM$27=TRUE,'Атлант, Великан'!$B$236*'Сроки и стоимость'!$N$71,0) | AP27: =IF($AM$27=TRUE,'Атлант, Великан'!$B$236*'Сроки и стоимость'!$N$71,0) | AQ27: =IF($AM$27=TRUE,'Атлант, Великан'!$B$236*'Сроки и стоимость'!$N$71,0) | AR27: =IF($AM$27=TRUE,'Атлант, Великан'!$B$236*'Сроки и стоимость'!$N$71,0) | AS27: =IF($AM$27=TRUE,'Атлант, Великан'!$B$236*'Сроки и стоимость'!$N$71,0) | AT27: =IF($AM$27=TRUE,'Атлант, Великан'!$B$236*'Сроки и стоимость'!$N$71,0) | AU27: =IF($AM$27=TRUE,'Атлант, Великан'!$B$236*'Сроки и стоимость'!$N$71,0) | AV27: =IF($AM$27=TRUE,'Атлант, Великан'!$B$236*'Сроки и стоимость'!$N$71,0) | ... BF27: =IF($AM$27=TRUE,'Атлант, Великан'!$B$236*'Сроки и стоимость'!$N$71,0) | BH27: с металлическими ступенями | BI27: одномаршевая | BJ27: =AM27
AL28: двухмаршевая | AM28: FALSE | AO28: =IF($AM$28=TRUE,'Атлант, Великан'!$B$237*'Сроки и стоимость'!$N$73,0) | AP28: =IF($AM$28=TRUE,'Атлант, Великан'!$B$237*'Сроки и стоимость'!$N$73,0) | AQ28: =IF($AM$28=TRUE,'Атлант, Великан'!$B$237*'Сроки и стоимость'!$N$73,0) | AR28: =IF($AM$28=TRUE,'Атлант, Великан'!$B$237*'Сроки и стоимость'!$N$73,0) | AS28: =IF($AM$28=TRUE,'Атлант, Великан'!$B$237*'Сроки и стоимость'!$N$73,0) | AT28: =IF($AM$28=TRUE,'Атлант, Великан'!$B$237*'Сроки и стоимость'!$N$73,0) | AU28: =IF($AM$28=TRUE,'Атлант, Великан'!$B$237*'Сроки и стоимость'!$N$73,0) | AV28: =IF($AM$28=TRUE,'Атлант, Великан'!$B$237*'Сроки и стоимость'!$N$73,0) | ... BF28: =IF($AM$28=TRUE,'Атлант, Великан'!$B$237*'Сроки и стоимость'!$N$73,0) | BI28: двухмаршевая | BJ28: =AM28
AL29: трехмаршевая | AM29: FALSE | AO29: =IF($AM$29=TRUE,'Атлант, Великан'!$B$238*'Сроки и стоимость'!$N$75,0) | AP29: =IF($AM$29=TRUE,'Атлант, Великан'!$B$238*'Сроки и стоимость'!$N$75,0) | AQ29: =IF($AM$29=TRUE,'Атлант, Великан'!$B$238*'Сроки и стоимость'!$N$75,0) | AR29: =IF($AM$29=TRUE,'Атлант, Великан'!$B$238*'Сроки и стоимость'!$N$75,0) | AS29: =IF($AM$29=TRUE,'Атлант, Великан'!$B$238*'Сроки и стоимость'!$N$75,0) | AT29: =IF($AM$29=TRUE,'Атлант, Великан'!$B$238*'Сроки и стоимость'!$N$75,0) | AU29: =IF($AM$29=TRUE,'Атлант, Великан'!$B$238*'Сроки и стоимость'!$N$75,0) | AV29: =IF($AM$29=TRUE,'Атлант, Великан'!$B$238*'Сроки и стоимость'!$N$75,0) | ... BF29: =IF($AM$29=TRUE,'Атлант, Великан'!$B$238*'Сроки и стоимость'!$N$75,0) | BI29: трехмаршевая | BJ29: =AM29
AL30: четырехмаршевая | AM30: FALSE | AO30: =IF($AM$30=TRUE,'Атлант, Великан'!$B$239*'Сроки и стоимость'!$N$77,0) | AP30: =IF($AM$30=TRUE,'Атлант, Великан'!$B$239*'Сроки и стоимость'!$N$77,0) | AQ30: =IF($AM$30=TRUE,'Атлант, Великан'!$B$239*'Сроки и стоимость'!$N$77,0) | AR30: =IF($AM$30=TRUE,'Атлант, Великан'!$B$239*'Сроки и стоимость'!$N$77,0) | AS30: =IF($AM$30=TRUE,'Атлант, Великан'!$B$239*'Сроки и стоимость'!$N$77,0) | AT30: =IF($AM$30=TRUE,'Атлант, Великан'!$B$239*'Сроки и стоимость'!$N$77,0) | AU30: =IF($AM$30=TRUE,'Атлант, Великан'!$B$239*'Сроки и стоимость'!$N$77,0) | AV30: =IF($AM$30=TRUE,'Атлант, Великан'!$B$239*'Сроки и стоимость'!$N$77,0) | ... BF30: =IF($AM$30=TRUE,'Атлант, Великан'!$B$239*'Сроки и стоимость'!$N$77,0) | BI30: четырехмаршевая | BJ30: =AM30
AK31: ограждающие конструкции | AL31: кровля | AM31: 3 | AO31: =CHOOSE($AM$31,'Атлант, Великан'!$B$285,'Атлант, Великан'!$B$284,'Атлант, Великан'!$B$285,'Атлант, Великан'!$B$285) | AP31: =CHOOSE($AM$31,'Атлант, Великан'!$B$285,'Атлант, Великан'!$B$284,'Атлант, Великан'!$B$285,'Атлант, Великан'!$B$285) | AQ31: =CHOOSE($AM$31,'Атлант, Великан'!$B$285,'Атлант, Великан'!$B$284,'Атлант, Великан'!$B$285,'Атлант, Великан'!$B$285) | AR31: =CHOOSE($AM$31,'Атлант, Великан'!$B$285,'Атлант, Великан'!$B$284,'Атлант, Великан'!$B$285,'Атлант, Великан'!$B$285) | AS31: =CHOOSE($AM$31,'Атлант, Великан'!$B$285,'Атлант, Великан'!$B$284,'Атлант, Великан'!$B$285,'Атлант, Великан'!$B$285) | AT31: =CHOOSE($AM$31,'Атлант, Великан'!$B$285,'Атлант, Великан'!$B$284,'Атлант, Великан'!$B$285,'Атлант, Великан'!$B$285) | AU31: =CHOOSE($AM$31,'Атлант, Великан'!$B$285,'Атлант, Великан'!$B$284,'Атлант, Великан'!$B$285,'Атлант, Великан'!$B$285) | AV31: =CHOOSE($AM$31,'Атлант, Великан'!$B$285,'Атлант, Великан'!$B$284,'Атлант, Великан'!$B$285,'Атлант, Великан'!$B$285) | ... BF31: =CHOOSE($AM$31,'Атлант, Великан'!$B$285,'Атлант, Великан'!$B$284,'Атлант, Великан'!$B$285,'Атлант, Великан'!$B$285) | BH31: ограждающие конструкции | BI31: кровля | BJ31: =AM31 | BL31: ='Атлант, Великан'!$L$476 | BM31: ='Атлант, Великан'!$L$476 | BN31: ='Атлант, Великан'!$L$476 | BO31: ='Атлант, Великан'!$L$476 | BP31: ='Атлант, Великан'!$L$476 | BQ31: ='Атлант, Великан'!$L$476 | BR31: ='Атлант, Великан'!$L$476 | BS31: ='Атлант, Великан'!$L$476 | ... CC31: ='Атлант, Великан'!$L$476
BJ32: =AM32
D33: 1 | AL33: снегозадержание | AM33: FALSE | AO33: =IF($AM$33=TRUE,'Атлант, Великан'!$B$289,0) | AP33: =IF($AM$33=TRUE,'Атлант, Великан'!$B$289,0) | AQ33: =IF($AM$33=TRUE,'Атлант, Великан'!$B$289,0) | AR33: =IF($AM$33=TRUE,'Атлант, Великан'!$B$289,0) | AS33: =IF($AM$33=TRUE,'Атлант, Великан'!$B$289,0) | AT33: =IF($AM$33=TRUE,'Атлант, Великан'!$B$289,0) | AU33: =IF($AM$33=TRUE,'Атлант, Великан'!$B$289,0) | AV33: =IF($AM$33=TRUE,'Атлант, Великан'!$B$289,0) | ... BF33: =IF($AM$33=TRUE,'Атлант, Великан'!$B$289,0) | BI33: снегозадержание | BJ33: =AM33 | BL33: =IF($BJ$33=FALSE,0,'Атлант, Великан'!$B$546) | BM33: =IF($BJ$33=FALSE,0,'Атлант, Великан'!$B$546) | BN33: =IF($BJ$33=FALSE,0,'Атлант, Великан'!$B$546) | BO33: =IF($BJ$33=FALSE,0,'Атлант, Великан'!$B$546) | BP33: =IF($BJ$33=FALSE,0,'Атлант, Великан'!$B$546) | BQ33: =IF($BJ$33=FALSE,0,'Атлант, Великан'!$B$546) | BR33: =IF($BJ$33=FALSE,0,'Атлант, Великан'!$B$546) | BS33: =IF($BJ$33=FALSE,0,'Атлант, Великан'!$B$546) | ... CC33: =IF($BJ$33=FALSE,0,'Атлант, Великан'!$B$546)
AL34: ограждение кровли | AM34: FALSE | AO34: =IF($AM$34=TRUE,'Атлант, Великан'!$B$287,0) | AP34: =IF($AM$34=TRUE,'Атлант, Великан'!$B$287,0) | AQ34: =IF($AM$34=TRUE,'Атлант, Великан'!$B$287,0) | AR34: =IF($AM$34=TRUE,'Атлант, Великан'!$B$287,0) | AS34: =IF($AM$34=TRUE,'Атлант, Великан'!$B$287,0) | AT34: =IF($AM$34=TRUE,'Атлант, Великан'!$B$287,0) | AU34: =IF($AM$34=TRUE,'Атлант, Великан'!$B$287,0) | AV34: =IF($AM$34=TRUE,'Атлант, Великан'!$B$287,0) | ... BF34: =IF($AM$34=TRUE,'Атлант, Великан'!$B$287,0) | BI34: ограждение кровли | BJ34: =AM34 | BL34: =IF($BJ$34=FALSE,0,'Атлант, Великан'!$B$544) | BM34: =IF($BJ$34=FALSE,0,'Атлант, Великан'!$B$544) | BN34: =IF($BJ$34=FALSE,0,'Атлант, Великан'!$B$544) | BO34: =IF($BJ$34=FALSE,0,'Атлант, Великан'!$B$544) | BP34: =IF($BJ$34=FALSE,0,'Атлант, Великан'!$B$544) | BQ34: =IF($BJ$34=FALSE,0,'Атлант, Великан'!$B$544) | BR34: =IF($BJ$34=FALSE,0,'Атлант, Великан'!$B$544) | BS34: =IF($BJ$34=FALSE,0,'Атлант, Великан'!$B$544) | ... CC34: =IF($BJ$34=FALSE,0,'Атлант, Великан'!$B$544)
B35: 12 | BJ35: =AM35
AL36: стены | AM36: 3 | AO36: ='Атлант, Великан'!$L$183 | AP36: ='Атлант, Великан'!$L$183 | AQ36: ='Атлант, Великан'!$L$183 | AR36: ='Атлант, Великан'!$L$183 | AS36: ='Атлант, Великан'!$L$183 | AT36: ='Атлант, Великан'!$L$183 | AU36: ='Атлант, Великан'!$L$183 | AV36: ='Атлант, Великан'!$L$183 | ... BF36: ='Атлант, Великан'!$L$183 | BI36: стены | BJ36: =AM36 | BL36: ='Атлант, Великан'!$L$481 | BM36: ='Атлант, Великан'!$L$481 | BN36: ='Атлант, Великан'!$L$481 | BO36: ='Атлант, Великан'!$L$481 | BP36: ='Атлант, Великан'!$L$481 | BQ36: ='Атлант, Великан'!$L$481 | BR36: ='Атлант, Великан'!$L$481 | BS36: ='Атлант, Великан'!$L$481 | ... CC36: ='Атлант, Великан'!$L$481
AL37: толщина стен | AM37: 2 | BI37: толщина стен | BJ37: =AM37
B38: 24.3 | AL38: наличие окон | AM38: TRUE | AO38: ='Атлант, Великан'!$L$191 | AP38: ='Атлант, Великан'!$L$191 | AQ38: ='Атлант, Великан'!$L$191 | AR38: ='Атлант, Великан'!$L$191 | AS38: ='Атлант, Великан'!$L$191 | AT38: ='Атлант, Великан'!$L$191 | AU38: ='Атлант, Великан'!$L$191 | AV38: ='Атлант, Великан'!$L$191 | ... BF38: ='Атлант, Великан'!$L$191 | BI38: наличие окон | BJ38: =AM38 | BL38: ='Атлант, Великан'!$G$502 | BM38: ='Атлант, Великан'!$G$502 | BN38: ='Атлант, Великан'!$G$502 | BO38: ='Атлант, Великан'!$G$502 | BP38: ='Атлант, Великан'!$G$502 | BQ38: ='Атлант, Великан'!$G$502 | BR38: ='Атлант, Великан'!$G$502 | BS38: ='Атлант, Великан'!$G$502 | ... CC38: ='Атлант, Великан'!$G$502
BJ39: =AM39
B40: 6.075 | AL40: наличие ворот | AM40: FALSE | AO40: ='Атлант, Великан'!$H$220 | AP40: ='Атлант, Великан'!$H$220 | AQ40: ='Атлант, Великан'!$H$220 | AR40: ='Атлант, Великан'!$H$220 | AS40: ='Атлант, Великан'!$H$220 | AT40: ='Атлант, Великан'!$H$220 | AU40: ='Атлант, Великан'!$H$220 | AV40: ='Атлант, Великан'!$H$220 | ... BF40: ='Атлант, Великан'!$H$220 | BI40: наличие ворот | BJ40: =AM40 | BL40: ='Атлант, Великан'!$G$508 | BM40: ='Атлант, Великан'!$G$508 | BN40: ='Атлант, Великан'!$G$508 | BO40: ='Атлант, Великан'!$G$508 | BP40: ='Атлант, Великан'!$G$508 | BQ40: ='Атлант, Великан'!$G$508 | BR40: ='Атлант, Великан'!$G$508 | BS40: ='Атлант, Великан'!$G$508 | ... CC40: ='Атлант, Великан'!$G$508
AL41: наличие дверей | AM41: TRUE | AO41: ='Атлант, Великан'!$L$194 | AP41: ='Атлант, Великан'!$L$194 | AQ41: ='Атлант, Великан'!$L$194 | AR41: ='Атлант, Великан'!$L$194 | AS41: ='Атлант, Великан'!$L$194 | AT41: ='Атлант, Великан'!$L$194 | AU41: ='Атлант, Великан'!$L$194 | AV41: ='Атлант, Великан'!$L$194 | ... BF41: ='Атлант, Великан'!$L$194 | BI41: наличие дверей | BJ41: =AM41 | BL41: ='Атлант, Великан'!$G$505 | BM41: ='Атлант, Великан'!$G$505 | BN41: ='Атлант, Великан'!$G$505 | BO41: ='Атлант, Великан'!$G$505 | BP41: ='Атлант, Великан'!$G$505 | BQ41: ='Атлант, Великан'!$G$505 | BR41: ='Атлант, Великан'!$G$505 | BS41: ='Атлант, Великан'!$G$505 | ... CC41: ='Атлант, Великан'!$G$505
...

Sheet Атлант, Великан
A1: великан однопролетный двускатный каркас КМ - | B1: 1.8 | E1: =F1*B1 | F1: 80 | G1: 0,3 колонна | H1: 0,7 ферма | I1: 0,15 СГ | J1: 0,15 СВ | K1: 0,5 остальное | Y1: ферма
A3: атлант однопролетный двускатный каркас КМ - | B3: 1.6 | E3: =F3*B3 | F3: 80 | G3: 0,3 колонна | H3: 0,5 балка | I3: 0,15 СГ | J3: 0,15 СВ | K3: 0,5 остальное | Y3: балка
A5: атлант-М однопролетный двускатный каркас КМ - | B5: 1.7 | E5: =F5*B5 | F5: 80 | G5: 0,25 колонна | H5: 0,65 б + зат | I5: 0,15 СГ | J5: 0,15 СВ | K5: 0,5 остальное | Y5: балка с затяжкой
A7: высота до 6 вкл - | B7: 0 | E7: =$F$1*B7 | F7: =E7+$E$1 | H7: 6 | I7: =IF('Сроки и стоимость'!$F$43<='Атлант, Великан'!H7,'Атлант, Великан'!B7,0)
A8: высота от 6 до 7 вкл - | B8: 0.25 | E8: =$F$1*B8 | F8: =E8+$E$1 | H8: 7 | I8: =IF(AND('Сроки и стоимость'!$F$43>'Атлант, Великан'!H7,'Сроки и стоимость'!$F$43<='Атлант, Великан'!H8),'Атлант, Великан'!B8,0) | Y8: за доп вертикальные связи по продольной стороне
A9: высота от 7 до 9 вкл - | B9: 0.5 | E9: =$F$1*B9 | F9: =E9+$E$1 | H9: 9 | I9: =IF(AND('Сроки и стоимость'!$F$43>'Атлант, Великан'!H8,'Сроки и стоимость'!$F$43<='Атлант, Великан'!H9),'Атлант, Великан'!B9,0) | Y9: за доп вертикальные связи по продольной стороне + распорки
A10: высота от 9 до 12 вкл - | B10: 1 | E10: =$F$1*B10 | F10: =E10+$E$1 | H10: 12 | I10: =IF(AND('Сроки и стоимость'!$F$43>'Атлант, Великан'!H9,'Сроки и стоимость'!$F$43<='Атлант, Великан'!H10),'Атлант, Великан'!B10,0) | Y10: за доп вертикальные связи по продольной стороне и торце + распорки
A11: высота от 12 - | B11: 0.75 | D11: за каждые 3 метра | E11: =$F$1*B11 | F11: =E11+$E$1 | G11: 3 | H11: 12 | I11: =IF('Сроки и стоимость'!$F$43>'Атлант, Великан'!H11,'Атлант, Великан'!B11*_xlfn.CEILING.MATH(('Сроки и стоимость'!$F$43-'Атлант, Великан'!H11)/'Атлант, Великан'!G11),0) | J11: =SUM(I7:I11) | Y11: за доп вертикальные связи
A13: кран опорный Великан, Аталант, Атлант-М - | B13: 0.75 | E13: =$F$1*B13 | F13: =E13+$E$1
A14: кран подвесной Великан, Аталант - | B14: 0.6 | E14: =$F$1*B14 | F14: =E14+$E$1
A16: великан однопролетный односкатный каркас КМ - | B16: 2 | E16: =F16*B16 | F16: 80 | Y16: за колонны и гор. и вертикальные связи
A18: атлант однопролетный односкатный каркас КМ - | B18: 1.8 | E18: =F18*B18 | F18: 80 | Y18: за колонны и гор. и вертикальные связи
A20: атлант-М однопролетный односкатный каркас КМ - | B20: 1.9 | E20: =F20*B20 | F20: 80 | Y20: за колонны и гор. и вертикальные связи
A22: высота до 4 вкл - | B22: 0 | E22: =$F$1*B22 | F22: =E22+$E$1 | H22: 4 | I22: =IF('Сроки и стоимость'!$F$43<='Атлант, Великан'!H22,'Атлант, Великан'!B22,0)
A23: высота от 4 до 6 вкл - | B23: 0.3 | E23: =$F$1*B23 | F23: =E23+$E$1 | H23: 6 | I23: =IF(AND('Сроки и стоимость'!$F$43>'Атлант, Великан'!H22,'Сроки и стоимость'!$F$43<='Атлант, Великан'!H23),'Атлант, Великан'!B23,0) | Y23: за доп вертикальные связи по продольной стороне
A24: высота от 6 до 9 вкл - | B24: 0.8 | E24: =$F$1*B24 | F24: =E24+$E$1 | H24: 9 | I24: =IF(AND('Сроки и стоимость'!$F$43>'Атлант, Великан'!H23,'Сроки и стоимость'!$F$43<='Атлант, Великан'!H24),'Атлант, Великан'!B24,0) | Y24: за доп вертикальные связи по продольной стороне + распорки
A25: высота от 9 до 12 вкл - | B25: 1.3 | E25: =$F$1*B25 | F25: =E25+$E$1 | H25: 12 | I25: =IF(AND('Сроки и стоимость'!$F$43>'Атлант, Великан'!H24,'Сроки и стоимость'!$F$43<='Атлант, Великан'!H25),'Атлант, Великан'!B25,0) | Y25: за доп вертикальные связи по продольной стороне и торце + распорки
A26: высота от 12 - | B26: 0.75 | D26: за каждые 3 метра | G26: 3 | H26: 12 | I26: =IF('Сроки и стоимость'!$F$43>'Атлант, Великан'!H26,'Атлант, Великан'!B26*_xlfn.CEILING.MATH(('Сроки и стоимость'!$F$43-'Атлант, Великан'!H26)/'Атлант, Великан'!G26),0) | J26: =SUM(I22:I26) | Y26: за доп вертикальные связи
A28: кран опорный Великан, Аталант, Атлант-М - | B28: 0.9 | E28: =$F$1*B28 | F28: =E28+$E$1 | Y28: вероятно разные сечения колонн
A29: кран подвесной Великан, Аталант - | B29: 0.7 | E29: =$F$1*B29 | F29: =E29+$E$1
A31: великан многопролетный двускатный каркас КМ - | B31: 1.8 | C31: 0.4 | D31: за каждый пролет после 1-го (за колонны) | E31: =G31*B31 | F31: =G31*C31 | G31: 80 | Y31: за колонны и гор. связи
A33: атлант многопролетный двускатный каркас КМ - | B33: 1.6 | C33: 0.4 | D33: за каждый пролет после 1-го (за колонны) | E33: =G33*B33 | F33: =G33*C33 | G33: 80 | Y33: за колонны и гор. связи
A35: атлант-М многопролетный двускатный каркас КМ - | B35: 1.7 | C35: 0.35 | D35: за каждый пролет после 1-го (за колонны) | E35: =G35*B35 | F35: =G35*C35 | G35: 80 | Y35: за колонны и гор. связи
A37: высота до 6 вкл - | B37: 0 | E37: =$F$1*B37 | F37: =E37+$E$1 | H37: 6 | I37: =IF('Сроки и стоимость'!$F$43<='Атлант, Великан'!H37,'Атлант, Великан'!B37,0)
A38: за каждый пролет - | B38: 0 | D38: -0,1+0,1*(n-1)², где n - кол-во пролетов | E38: =$F$1*B38 | F38: =E38+$E$1 | H38: 6 | I38: =IF('Сроки и стоимость'!$F$43<='Атлант, Великан'!H38,'Атлант, Великан'!B38-0.1+0.1*('Сроки и стоимость'!$D$33-1)^2,0)
A39: высота от 6 до 7 вкл - | B39: 0.25 | E39: =$F$1*B39 | F39: =E39+$E$1 | H39: 7 | I39: =IF(AND('Сроки и стоимость'!$F$43>'Атлант, Великан'!H37,'Сроки и стоимость'!$F$43<='Атлант, Великан'!H39),'Атлант, Великан'!B39,0) | Y39: за доп вертикальные связи по продольной стороне
A40: за каждый пролет - | B40: 0.15 | D40: +0,1*(n-1)², где n - кол-во пролетов | E40: =$F$1*B40 | F40: =E40+$E$1 | H40: 7 | I40: =IF(AND('Сроки и стоимость'!$F$43>'Атлант, Великан'!H38,'Сроки и стоимость'!$F$43<='Атлант, Великан'!H40),'Атлант, Великан'!B40+0.1*('Сроки и стоимость'!$D$33-1)^2,0) | Y40: за доп вертикальные связи по продольной стороне
A41: высота от 7 до 9 вкл - | B41: 0.5 | E41: =$F$1*B41 | F41: =E41+$E$1 | H41: 9 | I41: =IF(AND('Сроки и стоимость'!$F$43>'Атлант, Великан'!H39,'Сроки и стоимость'!$F$43<='Атлант, Великан'!H41),'Атлант, Великан'!B41,0) | Y41: за доп вертикальные связи по продольной стороне + распорки
A42: за каждый пролет - | B42: 0.3 | D42: +0,1*(n-1)², где n - кол-во пролетов | E42: =$F$1*B42 | F42: =E42+$E$1 | H42: 9 | I42: =IF(AND('Сроки и стоимость'!$F$43>'Атлант, Великан'!H40,'Сроки и стоимость'!$F$43<='Атлант, Великан'!H42),'Атлант, Великан'!B42+0.1*('Сроки и стоимость'!$D$33-1)^2,0) | Y42: за доп вертикальные связи по продольной стороне + распорки
A43: высота от 9 до 12 вкл - | B43: 1 | E43: =$F$1*B43 | F43: =E43+$E$1 | H43: 12 | I43: =IF(AND('Сроки и стоимость'!$F$43>'Атлант, Великан'!H41,'Сроки и стоимость'!$F$43<='Атлант, Великан'!H43),'Атлант, Великан'!B43,0) | Y43: за доп вертикальные связи по продольной стороне и торце + распорки
A44: за каждый пролет - | B44: 0.45 | D44: +0,1*(n-1)², где n - кол-во пролетов | E44: =$F$1*B44 | F44: =E44+$E$1 | H44: 12 | I44: =IF(AND('Сроки и стоимость'!$F$43>'Атлант, Великан'!H42,'Сроки и стоимость'!$F$43<='Атлант, Великан'!H44),'Атлант, Великан'!B44+0.1*('Сроки и стоимость'!$D$33-1)^2,0) | Y44: за доп вертикальные связи по продольной стороне и торце + распорки
A45: высота от 12 - | B45: 0.75 | D45: за каждые 3 метра | E45: =$F$1*B45 | F45: =E45+$E$1 | G45: 3 | H45: 12 | I45: =IF('Сроки и стоимость'!$F$43>'Атлант, Великан'!H45,'Атлант, Великан'!B45*_xlfn.CEILING.MATH(('Сроки и стоимость'!$F$43-'Атлант, Великан'!H45)/'Атлант, Великан'!G45),0) | Y45: за доп вертикальные связи + распорки
A46: за каждый пролет - | B46: 0.45 | D46: +0,1*(n-1)², где n - кол-во пролетов | E46: =$F$1*B46 | F46: =E46+$E$1 | H46: 12 | I46: =IF('Сроки и стоимость'!$F$43>'Атлант, Великан'!H46,'Атлант, Великан'!B46+0.1*('Сроки и стоимость'!$D$33-1)^2,0) | J46: =SUM(I37:I46)
A49: кран опорный в одном пролете Великан, Аталант, Атлант-М - | B49: 0.9 | E49: =$F$1*B49 | F49: =E49+$E$1 | Y49: за разные консоли под покрановые балки, разные сечения колонн
A50: за каждый пролет с краном Великан, Аталант, Атлант-М - | B50: 0.6 | E50: =$F$1*B50 | F50: =E50+$E$1
A51: за каждый пролет с другой грузоподъемностью Великан, Аталант, Атлант-М - | B51: 0.2 | E51: =$F$1*B51 | F51: =E51+$E$1
A52: кран подвесной в одном пролете Великан, Аталант - | B52: 0.7 | E52: =$F$1*B52 | F52: =E52+$E$1
A53: за каждый пролет с краном Великан, Аталант - | B53: 0.5 | E53: =$F$1*B53 | F53: =E53+$E$1
A54: за каждый пролет с другой грузоподъемностью Великан, Аталант - | B54: 0.2 | E54: =$F$1*B54 | F54: =E54+$E$1
A56: великан многопролетный односкатный каркас КМ - | B56: 2 | C56: 0.6 | D56: за каждый пролет после 1-го (за колонны) больше вероятность нового сечения колонны | E56: =G56*B56 | F56: =G56*C56 | G56: 80 | Y56: за колонны и гор. связи
...

Sheet Спринт
A2: спринт-М двускатный каркас КМ - базовая стомость 80 000 руб | B2: 1 | D2: 80
G3: 1
A4: пролет до 12 вкл - | B4: 0 | D4: =$D$2*B4 | E4: =D4+80 | F4: 12 | G4: =IF('Сроки и стоимость'!$B$35<=Спринт!$F4,Спринт!$B4,0)
A5: пролет от 12 до 15 вкл - | B5: 0.15 | D5: =$D$2*B5 | E5: =D5+80 | F5: 15 | G5: =IF(AND('Сроки и стоимость'!$B$35<=Спринт!$F5,'Сроки и стоимость'!$B$35>$F4),Спринт!$B5,0) | Q5: за доп гор. связи
A6: пролет от 15 до 18 вкл - | B6: 0.25 | D6: =$D$2*B6 | E6: =D6+80 | F6: 18 | G6: =IF(AND('Сроки и стоимость'!$B$35<=Спринт!$F6,'Сроки и стоимость'!$B$35>$F5),Спринт!$B6,0) | Q6: за доп гор. связи
A7: пролет от 18 до 21 вкл - | B7: 0.35 | D7: =$D$2*B7 | E7: =D7+80 | F7: 21 | G7: =IF(AND('Сроки и стоимость'!$B$35<=Спринт!$F7,'Сроки и стоимость'!$B$35>$F6),Спринт!$B7,0) | Q7: за доп гор. связи
A8: пролет от 21 до 24 вкл - | B8: 0.5 | D8: =$D$2*B8 | E8: =D8+80 | F8: 24 | G8: =IF(AND('Сроки и стоимость'!$B$35<=Спринт!$F8,'Сроки и стоимость'!$B$35>$F7),Спринт!$B8,IF('Сроки и стоимость'!$B$35>$F8,999,0)) | H8: =SUM(G4:G8) | Q8: за доп гор. связи
A10: высота до 6 вкл - | B10: 0 | D10: =$D$2*B10 | E10: =D10+80 | F10: 6 | G10: =IF('Сроки и стоимость'!$F$43<=F10,B10,0)
A11: высота от 6 до 8 вкл - | B11: 0.15 | D11: =$D$2*B11 | E11: =D11+80 | F11: 8 | G11: =IF(AND('Сроки и стоимость'!$F$43>F10,'Сроки и стоимость'!$F$43<=F11),B11,0) | Q11: за доп вертикальные связи по длиной стороне
A12: высота от 8 - | B12: 0.6 | D12: =$D$2*B12 | E12: =D12+80 | G12: =IF('Сроки и стоимость'!$F$43>F11,B12,0) | H12: =SUM(G10:G12) | Q12: за доп вертикальные связи по длиной стороне + в торце + гор. связи по периметру
A14: спринт-2М двускатный каркас КМ - | B14: 1.2 | D14: =$D$2*B14 | Q14: + шпренгельная затяжка +0,15
G15: 1
A16: пролет до 12 вкл - | B16: 0 | D16: =$D$2*B16 | E16: =D16+$D$14 | F16: 12 | G16: =IF('Сроки и стоимость'!$B$35<=Спринт!$F16,Спринт!$B16,0)
A17: пролет от 12 до 15 вкл - | B17: 0.25 | D17: =$D$2*B17 | E17: =D17+$D$14 | F17: 15 | G17: =IF(AND('Сроки и стоимость'!$B$35<=Спринт!$F17,'Сроки и стоимость'!$B$35>$F16),Спринт!$B17,0) | Q17: за доп гор. связи + шпренгельная затяжка +0,1
A18: пролет от 15 до 18 вкл - | B18: 0.4 | D18: =$D$2*B18 | E18: =D18+$D$14 | F18: 18 | G18: =IF(AND('Сроки и стоимость'!$B$35<=Спринт!$F18,'Сроки и стоимость'!$B$35>$F17),Спринт!$B18,0) | Q18: за доп гор. связи + шпренгельная затяжка +0,15
A19: пролет от 18 до 21 вкл - | B19: 0.55 | D19: =$D$2*B19 | E19: =D19+$D$14 | F19: 21 | G19: =IF(AND('Сроки и стоимость'!$B$35<=Спринт!$F19,'Сроки и стоимость'!$B$35>$F18),Спринт!$B19,0) | Q19: за доп гор. связи + шпренгельная затяжка +0,2
A20: пролет от 21 до 24 вкл - | B20: 0.7 | D20: =$D$2*B20 | E20: =D20+$D$14 | F20: 24 | G20: =IF(AND('Сроки и стоимость'!$B$35<=Спринт!$F20,'Сроки и стоимость'!$B$35>$F19),Спринт!$B20,IF('Сроки и стоимость'!$B$35>$F20,999,0)) | H20: =SUM(G16:G20) | Q20: за доп гор. связи + шпренгельная затяжка +0,2
A22: высота до 5 вкл - | B22: 0 | D22: =$D$2*B22 | E22: =D22+$D$14 | F22: 5 | G22: =IF('Сроки и стоимость'!$F$43<=F22,B22,0)
A23: высота от 5 до 8 вкл - | B23: 0.15 | D23: =$D$2*B23 | E23: =D23+$D$14 | F23: 8 | G23: =IF(AND('Сроки и стоимость'!$F$43>F22,'Сроки и стоимость'!$F$43<=F23),B23,0) | Q23: за доп вертикальные связи по длиной стороне
A24: высота от 8 - | B24: 0.6 | D24: =$D$2*B24 | E24: =D24+$D$14 | G24: =IF('Сроки и стоимость'!$F$43>F23,B24,0) | H24: =SUM(G22:G24) | Q24: за доп вертикальные связи по длиной стороне + в торце + гор. связи по периметру
A26: Крон двускатный каркас КМ - | B26: 1.3 | D26: =$D$2*B26 | Q26: сборка без планина рамы +0,8
G27: 1
A28: пролет до 12 вкл - | B28: 0 | D28: =$D$2*B28 | E28: =D28+$D$26 | F28: 12 | G28: =IF('Сроки и стоимость'!$B$35<=Спринт!$F28,Спринт!$B28,0)
A29: пролет от 12 до 18 вкл - | B29: 0.4 | D29: =$D$2*B29 | E29: =D29+$D$26 | F29: 18 | G29: =IF(AND('Сроки и стоимость'!$B$35<=Спринт!$F29,'Сроки и стоимость'!$B$35>$F28),Спринт!$B29,0) | Q29: за доп гор. связи + усложнение фермы
A30: пролет от 18 до 21 вкл - | B30: 0.8 | D30: =$D$2*B30 | E30: =D30+$D$26 | F30: 21 | G30: =IF(AND('Сроки и стоимость'!$B$35<=Спринт!$F30,'Сроки и стоимость'!$B$35>$F29),Спринт!$B30,0) | Q30: за доп гор. связи + усложнение фермы
A31: пролет от 21 до 24 вкл - | B31: 1.2 | D31: =$D$2*B31 | E31: =D31+$D$26 | F31: 24 | G31: =IF(AND('Сроки и стоимость'!$B$35<=Спринт!$F31,'Сроки и стоимость'!$B$35>$F30),Спринт!$B31,0) | Q31: за доп гор. связи + усложнение фермы
A32: пролет от 24 до 30 вкл - | B32: 1.6 | D32: =$D$2*B32 | E32: =D32+$D$26 | F32: 30 | G32: =IF(AND('Сроки и стоимость'!$B$35<=Спринт!$F32,'Сроки и стоимость'!$B$35>$F31),Спринт!$B32,IF('Сроки и стоимость'!$B$35>$F32,999,0)) | H32: =SUM(G28:G32) | Q32: за доп гор. связи + усложнение фермы
A34: высота до 5 вкл - | B34: 0 | D34: =$D$2*B34 | E34: =D34+$D$14 | F34: 5 | G34: =IF('Сроки и стоимость'!$F$43<=F34,B34,0)
A35: высота от 5 до 7 вкл - | B35: 0.15 | D35: =$D$2*B35 | E35: =D35+$D$14 | F35: 7 | G35: =IF(AND('Сроки и стоимость'!$F$43>F34,'Сроки и стоимость'!$F$43<=F35),B35,0) | Q35: за доп вертикальные связи по длиной стороне
A36: высота от 7 - | B36: 0.6 | D36: =$D$2*B36 | E36: =D36+$D$14 | G36: =IF('Сроки и стоимость'!$F$43>F35,B36,0) | H36: =SUM(G34:G36) | Q36: за доп вертикальные связи по длиной стороне + в торце + гор. связи по периметру
A38: спринт-М односкатный каркас КМ - | B38: 1.05 | D38: =$D$2*B38 | Q38: отсутствие затяжки -0,2, но сборка без плагина рамы +0,1 + разные вертикальные связи +0,15
G39: 1
A40: пролет до 6 вкл - | B40: 0 | D40: =$D$2*B40 | E40: =D40+$D$38 | F40: 6 | G40: =IF('Сроки и стоимость'!$B$35<=Спринт!$F40,Спринт!$B40,0)
A41: пролет от 6 до 7,5 вкл - | B41: 0.05 | D41: =$D$2*B41 | E41: =D41+$D$38 | F41: 7.5 | G41: =IF(AND('Сроки и стоимость'!$B$35<=Спринт!$F41,'Сроки и стоимость'!$B$35>$F40),Спринт!$B41,0) | Q41: за доп гор. связи
A42: пролет от 7,5 до 9 вкл - | B42: 0.1 | D42: =$D$2*B42 | E42: =D42+$D$38 | F42: 9 | G42: =IF(AND('Сроки и стоимость'!$B$35<=Спринт!$F42,'Сроки и стоимость'!$B$35>$F41),Спринт!$B42,0) | Q42: за доп гор. связи
A43: пролет от 9 до 10,5 вкл - | B43: 0.2 | D43: =$D$2*B43 | E43: =D43+$D$38 | F43: 10.5 | G43: =IF(AND('Сроки и стоимость'!$B$35<=Спринт!$F43,'Сроки и стоимость'!$B$35>$F42),Спринт!$B43,0) | Q43: за доп гор. связи
A44: пролет от 10,5 до 12 вкл - | B44: 0.25 | D44: =$D$2*B44 | E44: =D44+$D$38 | F44: 12 | G44: =IF(AND('Сроки и стоимость'!$B$35<=Спринт!$F44,'Сроки и стоимость'!$B$35>$F43),Спринт!$B44,IF('Сроки и стоимость'!$B$35>$F44,0,0)) | H44: =SUM(G40:G44) | Q44: за доп гор. связи
A46: высота до 5 вкл - | B46: 0 | D46: =$D$2*B46 | E46: =D46+$D$38 | F46: 5 | G46: =IF('Сроки и стоимость'!$F$43<=F46,B46,0)
A47: высота от 5 до 6 вкл - | B47: 0.15 | D47: =$D$2*B47 | E47: =D47+$D$38 | F47: 6 | G47: =IF(AND('Сроки и стоимость'!$F$43>F46,'Сроки и стоимость'!$F$43<=F47),B47,0) | Q47: за доп вертикальные связи по длиной стороне
A48: высота от 6 - | B48: 0.45 | D48: =$D$2*B48 | E48: =D48+$D$38 | G48: =IF('Сроки и стоимость'!$F$43>F47,B48,0) | H48: =SUM(G46:G48) | Q48: за доп вертикальные связи по длиной стороне + в торце + гор. связи по периметру
...
